Workbook
Name custos: ccustos!$A:$B

Sheet acervo
A1: numero | B1: situacao | C1: descricao | D1: complemento | E1: classificacao | F1: localizacao | G1: data_entrada | H1: valor_compra | I1: valor_atual | J1: ccustos
A2: 10001 | B2: ATIVO | C2: CADEIRA | D2: CADEIRA DE FERRO PATINA COM ALMOFADAS | E2: MÓVEIS E UTENSÍLIOS DE ESCRITÓRIO | F2: 14 - CASA DE MÁQUINAS | G2: 31/12/1996 | H2: 75.94 | I2: 64.54 | J2: =IFERROR(_xlfn.XLOOKUP(F2,ccustos!A:A,ccustos!B:B),"Sem termo") -> DEINFRA
A3: 10002 | B3: ATIVO | C3: MESA | D3: PARA DATILOGRAFIA LAMINADO NA COR MARROM | E3: MÓVEIS E UTENSÍLIOS DE ESCRITÓRIO | F3: 14 - CASA DE MÁQUINAS | G3: 06/12/2012 | H3: 0.1 | I3: 424.03 | J3: =IFERROR(_xlfn.XLOOKUP(F3,ccustos!A:A,ccustos!B:B),"Sem termo") -> DEINFRA
A4: 10003 | B4: ATIVO | C4: CADEIRA | D4: CADEIRA DE FERRO PATINA COM ALMOFADAS | E4: MÓVEIS E UTENSÍLIOS DE ESCRITÓRIO | F4: 14 - CASA DE MÁQUINAS | G4: 01/01/2002 | H4: 0.01 | I4: 86.06 | J4: =IFERROR(_xlfn.XLOOKUP(F4,ccustos!A:A,ccustos!B:B),"Sem termo") -> DEINFRA
A5: 10004 | B5: ATIVO | C5: CADEIRA | D5: CADEIRA GIRATORIA COR VINHO COM BRACOS E RODAS | E5: MÓVEIS E UTENSÍLIOS DE ESCRITÓRIO | F5: 13 - CORREDOR | G5: 31/01/1996 | H5: 158.36 | I5: 173.7 | J5: =IFERROR(_xlfn.XLOOKUP(F5,ccustos!A:A,ccustos!B:B),"Sem termo") -> SEPAT
A6: 10007 | B6: ATIVO | C6: CADEIRA | D6: CADEIRA GIRATORIA COR VERMELHA COM BRACOS E RODAS | E6: MÓVEIS E UTENSÍLIOS DE ESCRITÓRIO | F6: S3 - DEPÓSITO RAMPA | G6: 31/01/1996 | H6: 158.36 | I6: 173.7 | J6: =IFERROR(_xlfn.XLOOKUP(F6,ccustos!A:A,ccustos!B:B),"Sem termo") -> SEPAT
A7: 10036 | B7: ATIVO | C7: CADEIRA | D7: CADEIRA GIRATORIA COR VERMELHA COM BRACOS E RODAS | E7: MÓVEIS E UTENSÍLIOS DE ESCRITÓRIO | F7: S3 - DEPÓSITO RAMPA | G7: 31/01/1996 | H7: 158.36 | I7: 173.7 | J7: =IFERROR(_xlfn.XLOOKUP(F7,ccustos!A:A,ccustos!B:B),"Sem termo") -> SEPAT
A8: 10041 | B8: ATIVO | C8: APARELHO / MESA DE SOM | D8: STANER MOD. EQUALIZE | E8: MÁQUINAS E EQUIPAMENTOS | F8: 13 - PLENÁRIO | G8: 16/04/2007 | H8: 1300 | I8: 640.28 | J8: =IFERROR(_xlfn.XLOOKUP(F8,ccustos!A:A,ccustos!B:B),"Sem termo") -> SEPAT
A9: 10043 | B9: ATIVO | C9: APARELHO / MESA DE SOM | D9: AMPLIFICADOR NASHIVILLE SERIE NA1600 TR 00744 | E9: MÁQUINAS E EQUIPAMENTOS | F9: 13 - PLENÁRIO | G9: 30/09/1996 | H9: 528.29 | I9: 350.38 | J9: =IFERROR(_xlfn.XLOOKUP(F9,ccustos!A:A,ccustos!B:B),"Sem termo") -> SEPAT
A10: 10044 | B10: ATIVO | C10: AMPLIFICADOR DE SOM | D10: AMPLIFICADOR DE AUDIO;TIMES ONE;JX240;2K56JU27976; | E10: MÁQUINAS E EQUIPAMENTOS | F10: 04 - CCOM STUDIO | G10: 10/12/2010 | H10: 624 | I10: 640.28 | J10: =IFERROR(_xlfn.XLOOKUP(F10,ccustos!A:A,ccustos!B:B),"Sem termo") -> Sem termo
A11: 10045 | B11: ATIVO | C11: AMPLIFICADOR DE SOM | D11: AMPLIFICADOR DE AUDIO;SHURE;FP16A;SN; | E11: MÁQUINAS E EQUIPAMENTOS | F11: 13 - PLENÁRIO | G11: 10/12/2010 | H11: 1440 | I11: 581.96 | J11: =IFERROR(_xlfn.XLOOKUP(F11,ccustos!A:A,ccustos!B:B),"Sem termo") -> SEPAT
A12: 10046 | B12: ATIVO | C12: EQUALIZADOR DE SOM | D12: EQUALIZADOR GRAPHIC;FBQ;FBQ3102;L0258477668; | E12: MÁQUINAS E EQUIPAMENTOS | F12: 13 - PLENÁRIO | G12: 10/12/2010 | H12: 1120 | I12: 452.64 | J12: =IFERROR(_xlfn.XLOOKUP(F12,ccustos!A:A,ccustos!B:B),"Sem termo") -> SEPAT
A13: 10047 | B13: ATIVO | C13: APARELHO / MESA DE SOM | D13: AMPLIFICADOR MARCA STANER MOD PA2000 | E13: MÁQUINAS E EQUIPAMENTOS | F13: 13 - PLENÁRIO | G13: 08/02/2002 | H13: 667 | I13: 350.38 | J13: =IFERROR(_xlfn.XLOOKUP(F13,ccustos!A:A,ccustos!B:B),"Sem termo") -> SEPAT
... A1311: 12016 | B1311: ATIVO | C1311: ESTANTE | D1311: ESTANTE EM ACO COM 06 PRATELEIRAS NA COR CINZA | E1311: MÓVEIS E UTENSÍLIOS DE ESCRITÓRIO | F1311: S3 - DEPÓSITO SEPAT | G1311: 22/01/2001 | H1311: 45 | I1311: 64.86 | J1311: =IFERROR(_xlfn.XLOOKUP(F1311,ccustos!A:A,ccustos!B:B),"Sem termo") -> SEPAT
A1312: 12017 | B1312: ATIVO | C1312: ESTANTE | E1312: MÓVEIS E UTENSÍLIOS DE ESCRITÓRIO | F1312: S3 - DEPÓSITO RAMPA | G1312: 17/10/1997 | H1312: 145 | I1312: 45.52 | J1312: =IFERROR(_xlfn.XLOOKUP(F1312,ccustos!A:A,ccustos!B:B),"Sem termo") -> SEPAT
A1313: 12018 | B1313: ATIVO | C1313: ESTANTE | D1313: ESTANTE EM ACO COM 06 PRATELEIRAS NA COR CINZA | E1313: MÓVEIS E UTENSÍLIOS DE ESCRITÓRIO | F1313: S3 - DEPÓSITO RAMPA | G1313: 18/02/2001 | H1313: 45 | I1313: 64.86 | J1313: =IFERROR(_xlfn.XLOOKUP(F1313,ccustos!A:A,ccustos!B:B),"Sem termo") -> SEPAT
A1314: 12019 | B1314: ATIVO | C1314: ESTANTE | D1314: ESTANTE EM ACO COM 06 PRATELEIRAS NA COR CINZA | E1314: MÓVEIS E UTENSÍLIOS DE ESCRITÓRIO | F1314: S3 - DEPÓSITO SEPAT | G1314: 22/01/2001 | H1314: 45 | I1314: 64.86 | J1314: =IFERROR(_xlfn.XLOOKUP(F1314,ccustos!A:A,ccustos!B:B),"Sem termo") -> SEPAT
A1315: 12020 | B1315: ATIVO | C1315: ESTANTE | D1315: ESTANTE EM ACO COM 06 PRATELEIRAS NA COR CINZA | E1315: MÓVEIS E UTENSÍLIOS DE ESCRITÓRIO | F1315: S3 - DEPÓSITO SEPAT | G1315: 22/01/2001 | H1315: 45 | I1315: 64.86 | J1315: =IFERROR(_xlfn.XLOOKUP(F1315,ccustos!A:A,ccustos!B:B),"Sem termo") -> SEPAT
A1316: 12021 | B1316: ATIVO | C1316: ESTANTE | D1316: ESTANTE DE ACO COM 06 PRATELEIRAS 198x92x30cm | E1316: MÓVEIS E UTENSÍLIOS DE ESCRITÓRIO | F1316: S3 - DEPÓSITO SEPAT | G1316: 11/05/2001 | H1316: 49.9 | I1316: 64.86 | J1316: =IFERROR(_xlfn.XLOOKUP(F1316,ccustos!A:A,ccustos!B:B),"Sem termo") -> SEPAT
A1317: 12022 | B1317: ATIVO | C1317: ESTANTE | D1317: ESTANTE DE ACO COM 06 PRATELEIRAS 198x92x30cm | E1317: MÓVEIS E UTENSÍLIOS DE ESCRITÓRIO | F1317: S3 - DEPÓSITO RAMPA | G1317: 11/05/2001 | H1317: 49.9 | I1317: 64.86 | J1317: =IFERROR(_xlfn.XLOOKUP(F1317,ccustos!A:A,ccustos!B:B),"Sem termo") -> SEPAT
A1318: 12023 | B1318: ATIVO | C1318: ESTANTE | D1318: ESTANTE DE ACO COM 06 PRATELEIRAS 198x92x30cm | E1318: MÓVEIS E UTENSÍLIOS DE ESCRITÓRIO | F1318: S3 - DEPÓSITO RAMPA | G1318: 11/05/2001 | H1318: 49.9 | I1318: 64.86 | J1318: =IFERROR(_xlfn.XLOOKUP(F1318,ccustos!A:A,ccustos!B:B),"Sem termo") -> SEPAT
A1319: 12024 | B1319: ATIVO | C1319: ESTANTE | D1319: ESTANTE EM ACO COM 06 PRATELEIRAS NA COR CINZA | E1319: MÓVEIS E UTENSÍLIOS DE ESCRITÓRIO | F1319: S3 - DEPÓSITO RAMPA | G1319: 22/01/2001 | H1319: 45 | I1319: 64.86 | J1319: =IFERROR(_xlfn.XLOOKUP(F1319,ccustos!A:A,ccustos!B:B),"Sem termo") -> SEPAT
A1320: 12025 | B1320: ATIVO | C1320: ESTANTE | D1320: ESTANTE EM ACO COM 06 PRATELEIRAS NA COR CINZA | E1320: MÓVEIS E UTENSÍLIOS DE ESCRITÓRIO | F1320: S2 - ARQUIVO CENTRAL | G1320: 22/01/2001 | H1320: 45 | I1320: 64.86 | J1320: =IFERROR(_xlfn.XLOOKUP(F1320,ccustos!A:A,ccustos!B:B),"Sem termo") -> SEGED
A1321: 12026 | B1321: ATIVO | C1321: ESTANTE | D1321: ESTANTE DE ACO COM 06 PRATELEIRAS 198x92x30cm | E1321: MÓVEIS E UTENSÍLIOS DE ESCRITÓRIO | F1321: S2 - ARQUIVO CENTRAL | G1321: 11/05/2001 | H1321: 49.9 | I1321: 64.86 | J1321: =IFERROR(_xlfn.XLOOKUP(F1321,ccustos!A:A,ccustos!B:B),"Sem termo") -> SEGED
A1322: 12027 | B1322: ATIVO | C1322: ESTANTE | D1322: ESTANTE DE ACO COM 06 PRATELEIRAS 198x92x30cm | E1322: MÓVEIS E UTENSÍLIOS DE ESCRITÓRIO | F1322: S2 - ARQUIVO CENTRAL | G1322: 11/05/2001 | H1322: 49.9 | I1322: 64.86 | J1322: =IFERROR(_xlfn.XLOOKUP(F1322,ccustos!A:A,ccustos!B:B),"Sem termo") -> SEGED
A1323: 12028 | B1323: ATIVO | C1323: ESTANTE | D1323: ESTANTE DE ACO COM 06 PRATELEIRAS 198x92x30cm | E1323: MÓVEIS E UTENSÍLIOS DE ESCRITÓRIO | F1323: S2 - ARQUIVO CENTRAL | G1323: 11/05/2001 | H1323: 49.9 | I1323: 64.86 | J1323: =IFERROR(_xlfn.XLOOKUP(F1323,ccustos!A:A,ccustos!B:B),"Sem termo") -> SEGED
A1324: 12029 | B1324: ATIVO | C1324: ESTANTE | D1324: ESTANTE EM ACO COM 06 PRATELEIRAS NA COR CINZA | E1324: MÓVEIS E UTENSÍLIOS DE ESCRITÓRIO | F1324: S3 - DEPÓSITO SEPAT | G1324: 22/01/2001 | H1324: 45 | I1324: 64.86 | J1324: =IFERROR(_xlfn.XLOOKUP(F1324,ccustos!A:A,ccustos!B:B),"Sem termo") -> SEPAT
... A3142: 14950 | B3142: ATIVO | C3142: GAVETEIRO | D3142: VOLANTE COM 3 GAVETAS. COR OVO. 410 X 450 X 503MM | E3142: MÓVEIS E UTENSÍLIOS DE ESCRITÓRIO | F3142: S3 - DEPÓSITO SEPAT | G3142: 24/03/2025 | H3142: 950 | I3142: 950 | J3142: =IFERROR(_xlfn.XLOOKUP(F3142,ccustos!A:A,ccustos!B:B),"Sem termo") -> SEPAT
A3143: 14951 | B3143: ATIVO | C3143: LEITURA OPTICA | D3143: DE CODIGO DE BARRAS EYOYO EY-015 | E3143: EQUIPAMENTOS DE PROCESSAMENTO DE DADOS | F3143: 09 - CDPROF | G3143: 09/04/2025 | H3143: 387 | I3143: 387
A3144: 14952 | B3144: ATIVO | C3144: LEITURA OPTICA | D3144: DE CODIGO DE BARRAS EYOYO EY-015 | E3144: EQUIPAMENTOS DE PROCESSAMENTO DE DADOS | F3144: 09 - CDPROF | G3144: 09/04/2025 | H3144: 387 | I3144: 387
A3145: 14953 | B3145: ATIVO | C3145: LEITURA OPTICA | D3145: DE CODIGO DE BARRAS EYOYO EY-015 | E3145: EQUIPAMENTOS DE PROCESSAMENTO DE DADOS | F3145: 09 - CDPROF | G3145: 09/04/2025 | H3145: 387 | I3145: 387
A3146: 14954 | B3146: ATIVO | C3146: LEITURA OPTICA | D3146: DE CODIGO DE BARRAS EYOYO EY-015 | E3146: EQUIPAMENTOS DE PROCESSAMENTO DE DADOS | F3146: 09 - CDPROF | G3146: 09/04/2025 | H3146: 387 | I3146: 387
A3147: 14955 | B3147: ATIVO | C3147: LEITURA OPTICA | D3147: DE CODIGO DE BARRAS EYOYO EY-015 | E3147: EQUIPAMENTOS DE PROCESSAMENTO DE DADOS | F3147: 09 - CDPROF | G3147: 09/04/2025 | H3147: 387 | I3147: 387
A3148: 14956 | B3148: ATIVO | C3148: LEITURA OPTICA | D3148: DE CODIGO DE BARRAS EYOYO EY-015 | E3148: EQUIPAMENTOS DE PROCESSAMENTO DE DADOS | F3148: 09 - CDPROF | G3148: 09/04/2025 | H3148: 387 | I3148: 387
A3149: 14957 | B3149: ATIVO | C3149: LEITURA OPTICA | D3149: DE CODIGO DE BARRAS EYOYO EY-015 | E3149: EQUIPAMENTOS DE PROCESSAMENTO DE DADOS | F3149: 09 - CDPROF | G3149: 09/04/2025 | H3149: 387 | I3149: 387
A3150: 14958 | B3150: ATIVO | C3150: LEITURA OPTICA | D3150: DE CODIGO DE BARRAS EYOYO EY-015 | E3150: EQUIPAMENTOS DE PROCESSAMENTO DE DADOS | F3150: 09 - CDPROF | G3150: 09/04/2025 | H3150: 387 | I3150: 387
A3151: 14959 | B3151: ATIVO | C3151: LEITURA OPTICA | D3151: DE CODIGO DE BARRAS EYOYO EY-015 | E3151: EQUIPAMENTOS DE PROCESSAMENTO DE DADOS | F3151: 09 - CDPROF | G3151: 09/04/2025 | H3151: 387 | I3151: 387
A3152: 14960 | B3152: ATIVO | C3152: LEITURA OPTICA | D3152: DE CODIGO DE BARRAS EYOYO EY-015 | E3152: EQUIPAMENTOS DE PROCESSAMENTO DE DADOS | F3152: 09 - CDPROF | G3152: 09/04/2025 | H3152: 387 | I3152: 387
A3153: 14961 | B3153: ATIVO | C3153: LEITURA OPTICA | D3153: DE CODIGO DE BARRAS EYOYO EY-015 | E3153: EQUIPAMENTOS DE PROCESSAMENTO DE DADOS | F3153: 09 - CDPROF | G3153: 09/04/2025 | H3153: 387 | I3153: 387
A3154: 14962 | B3154: ATIVO | C3154: LEITURA OPTICA | D3154: DE CODIGO DE BARRAS EYOYO EY-015 | E3154: EQUIPAMENTOS DE PROCESSAMENTO DE DADOS | F3154: 09 - CDPROF | G3154: 09/04/2025 | H3154: 387 | I3154: 387
...

Sheet responsavel
A1: ccustos | B1: tratamento | C1: responsavel | D1: email | E1: matricula | F1: funcao
A2: CCI | B2: Prezada | C2: JAQUELINE RODRIGUES PORTELA ELMIRO | D2: jaqueline.elmiro@cfc.org.br | E2: 46 | F2: coordenadora
A3: DECOM | B3: Prezado | C3: THIAGO LUIS GOMES | D3: thiago.gomes@cfc.org.br | E3: 481 | F3: gerente
A4: CGGE | B4: Prezado | C4: CESAR ROBERTO BUZZIN | D4: crbuzzin@cfc.org.br | E4: 65 | F4: coordenador
A5: CDPROF | B5: Prezada | C5: JANAINA ANGELICA SARMENTO F. DE L. DE CARVALHO | D5: janaina.carvalho@cfc.org.br | E5: 331 | F5: coordenadora
A6: CGTI | B6: Prezada | C6: ANDREA RODRIGUES ROSA | D6: andrearosa@cfc.org.br | E6: 249 | F6: coordenadora
A7: COAD | B7: Prezada | C7: EUNICE ROSA DE MELO DOS SANTOS | D7: eunice@cfc.org.br | E7: 213 | F7: coordenadora
A8: COFIS | B8: Prezada | C8: FRANCIELE CARINI | D8: franciele@cfc.org.br | E8: 456 | F8: coordenadora
A9: COLOG | B9: Prezada | C9: PAULA MARIA ROCHA E SILVA | D9: paularocha@cfc.org.br | E9: 160 | F9: coordenadora
A10: COPI | B10: Prezada | C10: LUDMILA DE MELLO CORREA SILVA | D10: ludmello@cfc.org.br | E10: 201 | F10: coordenadora
A11: COREG | B11: Prezado | C11: EDSON CASSIO MIRANDA RODRIGUES PEREIRA | D11: edsonrodrigues@cfc.org.br | E11: 188 | F11: coordenador
A12: COTEC | B12: Prezado | C12: RICARDO DA SILVA CARVALHO | D12: ricardo.carvalho@cfc.org.br | E12: 479 | F12: coordenador
A13: DECONT | B13: Prezada | C13: ANGELA MARIA FAZION PEREIRA | D13: angela.fazion@cfc.org.br | E13: 374 | F13: gerente
... A32: CCOM | B32: Prezado | C32: DANIEL AMARAL GUERRA | D32: daniel.guerra@cfc.org.br | E32: 981 | F32: coordenador

Sheet ccustos
A1: localizacao | B1: ccustos
A2: 02 - CCOM | B2: CCOM
A3: 02 - CORREDOR | B3: SEPAT
A4: 02 - DECOM | B4: CCOM
A5: 03 - CGTI | B5: CGTI
A6: 03 - CORREDOR | B6: SEPAT
A7: 03 - CPD | B7: CGTI
A8: 03 - DEINF. | B8: CGTI
A9: 02 - DEMIDIA | B9: CCOM
A10: 04 - CORREDOR | B10: SEPAT
A11: 04 - DIEPG | B11: DIEPG
A12: 04 - DIGEO | B12: DIGEO
... A106: TERMOS INDIVIDUAIS | B106: TERMOS INDIVIDUAIS

Sheet Planilha1
A1: Número do bem | B1: Descrição | C1: Localização Anterior
A2: 10707 | B2: Mesa oval bege | C2: 04 - SALA DE REUNIÃO
A3: 12209 | B3: Cadeira fixa bege | C3: MOBILIÁRIO PARA ALIENAÇÃO
A4: 11198 | B4: Cadeira fixa bege | C4: S3 - DEPÓSITO RAMPA
A5: 11073 | B5: Cadeira fixa bege | C5: MOBILIÁRIO PARA ALIENAÇÃO
A6: 11511 | B6: Cadeira fixa bege | C6: MOBILIÁRIO PARA ALIENAÇÃO
A7: 10378 | B7: Mesa de canto – madeira | C7: 02 - DECOM
A8: 10379 | B8: Mesa quadrada – madeira | C8: S3 - DEPÓSITO RAMPA
A9: 10362 | B9: Poltrona azul | C9: S3 - DEPÓSITO RAMPA
A10: 10361 | B10: Poltrona azul | C10: S3 - DEPÓSITO RAMPA
A11: 10360 | B11: Poltrona azul | C11: S3 - DEPÓSITO RAMPA
A12: 13103 | B12: Monitor HP | C12: 03 - CGTI
